<robot name="my_simulation_robot">
    <!-- creating the root link -->
    <link name="world"/>

    <!-- adding a fixed joint to attach base of the robot to the world -->
    <joint name="world_to_base" type="fixed">
        <parent link="world"/> <!-- parent link is the world -->
        <child link="base_link"/> <!-- child link is the base of the robot -->
    </joint>

    <!-- creating the vertical robot base link -->
    <link name="base_link">
        <visual> <!-- the base of the robot will be a vertical box -->
            <geometry>
                <box size="0.2 0.2 0.5"/> <!-- box with width 0.2, depth 0.2, and height 0.5 -->
            </geometry>
            <material name="lime"> <!-- lime color for the vertical base -->
                <color rgba="0 1 0 1"/> <!-- lime green -->
            </material>
        </visual>
        <collision>
            <geometry>
                <box size="0.2 0.2 0.5"/> <!-- collision geometry matching the visual -->
            </geometry>
        </collision>
        <inertial>
            <mass value="1.0"/> <!-- mass of the vertical base -->
            <inertia ixx="0.1" ixy="0.0" ixz="0.0" iyy="0.1" iyz="0.0" izz="0.1"/> <!-- inertia tensor for the base -->
        </inertial>
    </link>

    <!-- adding the front left wheel -->
    <link name="front_left_wheel">
        <visual>
            <geometry>
                <cylinder length="0.05" radius="0.05"/> <!-- cylinder for the wheel -->
            </geometry>
            <material name="black">
                <color rgba="0 0 0 1"/> <!-- black color for the wheel -->
            </material>
        </visual>
        <collision>
            <geometry>
                <cylinder length="0.05" radius="0.05"/> <!-- collision geometry for the wheel -->
            </geometry>
        </collision>
        <inertial>
            <mass value="0.2"/> <!-- mass of the wheel -->
            <inertia ixx="0.0001" ixy="0.0" ixz="0.0" iyy="0.0001" iyz="0.0" izz="0.0001"/>
        </inertial>
    </link>

    <joint name="front_left_wheel_joint" type="continuous">
        <parent link="base_link"/>
        <child link="front_left_wheel"/>
        <origin xyz="0.1 0.1 -0.25" rpy="0 1.5708 0"/> <!-- position of the front left wheel relative to the base -->
        <axis xyz="0 1 0"/> <!-- rotation axis -->
    </joint>

    <!-- adding the front right wheel -->
    <link name="front_right_wheel">
        <visual>
            <geometry>
                <cylinder length="0.05" radius="0.05"/> <!-- cylinder for the wheel -->
            </geometry>
            <material name="black">
                <color rgba="0 0 0 1"/> <!-- black color for the wheel -->
            </material>
        </visual>
        <collision>
            <geometry>
                <cylinder length="0.05" radius="0.05"/> <!-- collision geometry for the wheel -->
            </geometry>
        </collision>
        <inertial>
            <mass value="0.2"/> <!-- mass of the wheel -->
            <inertia ixx="0.0001" ixy="0.0" ixz="0.0" iyy="0.0001" iyz="0.0" izz="0.0001"/>
        </inertial>
    </link>

    <joint name="front_right_wheel_joint" type="continuous">
        <parent link="base_link"/>
        <child link="front_right_wheel"/>
        <origin xyz="0.1 -0.1 -0.25" rpy="0 1.5708 0"/> <!-- position of the front right wheel relative to the base -->
        <axis xyz="0 1 0"/> <!-- rotation axis -->
    </joint>

    <!-- adding the rear left wheel -->
    <link name="rear_left_wheel">
        <visual>
            <geometry>
                <cylinder length="0.05" radius="0.05"/> <!-- cylinder for the wheel -->
            </geometry>
            <material name="black">
                <color rgba="0 0 0 1"/> <!-- black color for the wheel -->
            </material>
        </visual>
        <collision>
            <geometry>
                <cylinder length="0.05" radius="0.05"/> <!-- collision geometry for the wheel -->
            </geometry>
        </collision>
        <inertial>
            <mass value="0.2"/> <!-- mass of the wheel -->
            <inertia ixx="0.0001" ixy="0.0" ixz="0.0" iyy="0.0001" iyz="0.0" izz="0.0001"/>
        </inertial>
    </link>

    <joint name="rear_left_wheel_joint" type="continuous">
        <parent link="base_link"/>
        <child link="rear_left_wheel"/>
        <origin xyz="-0.1 0.1 -0.25" rpy="0 1.5708 0"/> <!-- position of the rear left wheel relative to the base -->
        <axis xyz="0 1 0"/> <!-- rotation axis -->
    </joint>

    <!-- adding the rear right wheel -->
    <link name="rear_right_wheel">
        <visual>
            <geometry>
                <cylinder length="0.05" radius="0.05"/> <!-- cylinder for the wheel -->
            </geometry>
            <material name="black">
                <color rgba="0 0 0 1"/> <!-- black color for the wheel -->
            </material>
        </visual>
        <collision>
            <geometry>
                <cylinder length="0.05" radius="0.05"/> <!-- collision geometry for the wheel -->
            </geometry>
        </collision>
        <inertial>
            <mass value="0.2"/> <!-- mass of the wheel -->
            <inertia ixx="0.0001" ixy="0.0" ixz="0.0" iyy="0.0001" iyz="0.0" izz="0.0001"/>
        </inertial>
    </link>

    <joint name="rear_right_wheel_joint" type="continuous">
        <parent link="base_link"/>
        <child link="rear_right_wheel"/>
        <origin xyz="-0.1 -0.1 -0.25" rpy="0 1.5708 0"/> <!-- position of the rear right wheel relative to the base -->
        <axis xyz="0 1 0"/> <!-- rotation axis -->
    </joint>

    <!-- adding the left gripper arm -->
    <link name="gripper_arm">
        <visual>
            <geometry>
                <box size="0.3 0.02 0.02"/> <!-- arm extending outward -->
            </geometry>
            <material name="black">
                <color rgba="0 0 0 1"/> <!-- black color -->
            </material>
        </visual>
        <collision>
            <geometry>
                <box size="0.3 0.02 0.02"/>
            </geometry>
        </collision>
        <inertial>
            <mass value="0.1"/>
            <inertia ixx="0.00001" ixy="0.0" ixz="0.0" iyy="0.00001" iyz="0.0" izz="0.00001"/>
        </inertial>
    </link>

    <joint name="gripper_arm_joint" type="revolute">
        <parent link="base_link"/>
        <child link="gripper_arm"/>
        <origin xyz="0 0 0.2" rpy="0 0 0"/> <!-- arm extending outward from the left side of the base -->
        <axis xyz="0 1 0"/>
        <limit lower="-1.5708" upper="1.5708" effort="10" velocity="0.05"/>
    </joint>

</robot>

